2021-11-16 16:31:08,530 INFO: Microblog startup [in /Users/andrey/Projects/flask_project/app/__init__.py:53]
2021-11-16 16:31:19,503 ERROR: Exception on /edit_profile [POST] [in /Users/andrey/Projects/flask_project/venv/lib/python3.9/site-packages/flask/app.py:1457]
Traceback (most recent call last):
  File "/Users/andrey/Projects/flask_project/venv/lib/python3.9/site-packages/flask/app.py", line 2073, in wsgi_app
    response = self.full_dispatch_request()
  File "/Users/andrey/Projects/flask_project/venv/lib/python3.9/site-packages/flask/app.py", line 1518, in full_dispatch_request
    rv = self.handle_user_exception(e)
  File "/Users/andrey/Projects/flask_project/venv/lib/python3.9/site-packages/flask/app.py", line 1516, in full_dispatch_request
    rv = self.dispatch_request()
  File "/Users/andrey/Projects/flask_project/venv/lib/python3.9/site-packages/flask/app.py", line 1502, in dispatch_request
    return self.ensure_sync(self.view_functions[rule.endpoint])(**req.view_args)
  File "/Users/andrey/Projects/flask_project/venv/lib/python3.9/site-packages/flask_login/utils.py", line 272, in decorated_view
    return func(*args, **kwargs)
  File "/Users/andrey/Projects/flask_project/app/routes.py", line 98, in edit_profile
    if form.validate_on_submit():
  File "/Users/andrey/Projects/flask_project/venv/lib/python3.9/site-packages/flask_wtf/form.py", line 86, in validate_on_submit
    return self.is_submitted() and self.validate()
  File "/Users/andrey/Projects/flask_project/venv/lib/python3.9/site-packages/wtforms/form.py", line 329, in validate
    return super().validate(extra)
  File "/Users/andrey/Projects/flask_project/venv/lib/python3.9/site-packages/wtforms/form.py", line 146, in validate
    if not field.validate(self, extra):
  File "/Users/andrey/Projects/flask_project/venv/lib/python3.9/site-packages/wtforms/fields/core.py", line 242, in validate
    stop_validation = self._run_validation_chain(form, chain)
  File "/Users/andrey/Projects/flask_project/venv/lib/python3.9/site-packages/wtforms/fields/core.py", line 262, in _run_validation_chain
    validator(form, self)
  File "/Users/andrey/Projects/flask_project/app/forms.py", line 45, in validate_username
    if username.data != self.original_username:
NameError: name 'username' is not defined
2021-11-16 16:37:39,962 INFO: Microblog startup [in /Users/andrey/Projects/flask_project/app/__init__.py:53]
2021-11-16 16:37:59,937 ERROR: Exception on /edit_profile [POST] [in /Users/andrey/Projects/flask_project/venv/lib/python3.9/site-packages/flask/app.py:1457]
Traceback (most recent call last):
  File "/Users/andrey/Projects/flask_project/venv/lib/python3.9/site-packages/flask/app.py", line 2073, in wsgi_app
    response = self.full_dispatch_request()
  File "/Users/andrey/Projects/flask_project/venv/lib/python3.9/site-packages/flask/app.py", line 1518, in full_dispatch_request
    rv = self.handle_user_exception(e)
  File "/Users/andrey/Projects/flask_project/venv/lib/python3.9/site-packages/flask/app.py", line 1516, in full_dispatch_request
    rv = self.dispatch_request()
  File "/Users/andrey/Projects/flask_project/venv/lib/python3.9/site-packages/flask/app.py", line 1502, in dispatch_request
    return self.ensure_sync(self.view_functions[rule.endpoint])(**req.view_args)
  File "/Users/andrey/Projects/flask_project/venv/lib/python3.9/site-packages/flask_login/utils.py", line 272, in decorated_view
    return func(*args, **kwargs)
  File "/Users/andrey/Projects/flask_project/app/routes.py", line 98, in edit_profile
    if form.validate_on_submit():
  File "/Users/andrey/Projects/flask_project/venv/lib/python3.9/site-packages/flask_wtf/form.py", line 86, in validate_on_submit
    return self.is_submitted() and self.validate()
  File "/Users/andrey/Projects/flask_project/venv/lib/python3.9/site-packages/wtforms/form.py", line 329, in validate
    return super().validate(extra)
  File "/Users/andrey/Projects/flask_project/venv/lib/python3.9/site-packages/wtforms/form.py", line 146, in validate
    if not field.validate(self, extra):
  File "/Users/andrey/Projects/flask_project/venv/lib/python3.9/site-packages/wtforms/fields/core.py", line 242, in validate
    stop_validation = self._run_validation_chain(form, chain)
  File "/Users/andrey/Projects/flask_project/venv/lib/python3.9/site-packages/wtforms/fields/core.py", line 262, in _run_validation_chain
    validator(form, self)
  File "/Users/andrey/Projects/flask_project/app/forms.py", line 45, in validate_username
    if username.data != self.original_username:
NameError: name 'username' is not defined
2021-11-16 16:43:04,819 INFO: Microblog startup [in /Users/andrey/Projects/flask_project/app/__init__.py:53]
2021-11-16 17:27:11,921 INFO: Microblog startup [in /Users/andrey/Projects/flask_project/app/__init__.py:53]
2021-11-16 17:27:25,134 INFO: Microblog startup [in /Users/andrey/Projects/flask_project/app/__init__.py:53]
